# 异常

## 1. 异常语法

C++异常是对程序运行过程中发生的异常情况(例如被0除)的一种响应。

异常提供了将控制权从程序的一个部分传递到另一部分的途径。



对异常的处理有3个组成部分：

- 引发异常；
- 使用处理程序捕获异常；
- 使用 try 块。



```cpp
int sum(int x, int y) {
	if (x < 0 || y < 0) {
		throw "x or y < 0!";
	}
	return x + y;
}

int main(void) {
	
	try {
		sum(-1,1);
	}
	catch (const char * C_str) {
		cout << C_str << endl;
	}

	return 0;
}
```



如果一个C++函数抛出了异常，但是这个函数没有在`try`语句块中被调用，那么这个异常将不会被捕获，该异常称之为**未捕获异常**。

throw 可以抛出任何类型的异常，但每次只能抛出一个异常。（一个参数，如果需要多个可以封装到类、结构等中）。

catch关键字捕获异常，随后是位于括号中的类型声明，它指出了异常处理程序要响应的异常类型，用花括号括起的代码块，指出要采取的措施。

---

catch关键字根据，括号中的类型声明来捕获异常。

```cpp
void test(int x){

	if(x ==1 ){
		throw (int)(1);
	}else if( x == 2){
		throw (double)(1.0);
	}else if (x == 3){
		throw (char)('a');
	}

}

int main(void){
    
    try{
        test(1);
    }
    catch(int p){
        cout << "int try:" << p << endl;
    }
    catch(double p){
        cout << "double try:" << p << endl;
    }
    catch(char p){
        cout << "char try:" << p << endl;
    }
    
    try{
        test(3);
    }
    catch(int p){
        cout << "int try:" << p << endl;
    }
    catch(double p){
        cout << "double try:" << p << endl;
    }
    catch(char p){
        cout << "char try:" << p << endl;
    }
    
}
```

运行结果：

```
int try:1
char try:3
```

---

**重新抛出异常**

重新抛出异常是指在catch块中使用throw语句，但不带任何参数。

这将导致当前处理的异常被重新抛出，**重新抛出异常的类型和参数的值**与**原异常一致**。

```cpp
#include <iostream>

void function2() {
    throw 1;  // 抛出一个整数类型的异常     类型为int 值为1
}

void function1() {
    try {
        function2();
    } catch (int e) {
        std::cout << "Caught an exception in function1: " << e << std::endl;
        throw;  // 重新抛出异常			类型为int 值为1    与原异常一致
    }
}

int main() {
    try {
        function1();
    } catch (int e) {
        std::cout << "Caught an exception in main: " << e << std::endl;
    }

    return 0;
}

```



## 2. 异常规范

这是 C++98 新增的一项功能，但 C++11却将其摒弃了。这意味着 C++11 仍然处于标准之中，但以后可能会从标准中剔除，因此不建议您使用它。



在函数声明后使用 `throw` 关键字来指定该函数可能抛出的异常类型：

```cpp
double harm(double a) throw(bad_thing); // 可能抛出 bad_thing 异常
double harm(double a) throw();			// 不会抛出任何异常
```

异常规范的作用之一是，告诉用户可能需要使用try块，这项工作也可使用注释轻松地完成。

异常规范的另一个作用是，让编译器添加执行运行阶段检查的代码，检查是否违反了异常规范。

这很难检查。例如，marm()可能不会引发异常，但它可能调用一个函数，而这个函数调用的另一个函数引发了异常。

给函数编写代码时它不会引发异常，但库更新后它却会引发异常。



C++11 标准已经废弃了异常规范，并引入了新的关键字 `noexcept`，用于指定函数不会抛出任何异常。

```cpp
double marm(double a) noexcept; // 不会抛出任何异常
```



## 3. 栈解退

当一个函数抛出一个异常时，程序需要找到一个能处理这个异常的代码块。

这个过程涉及到从当前函数开始，逐级向上回溯（也就是“解退”）函数调用栈，直到找到一个包含能处理这个异常的 try-catch 块的函数。

引发机制的一个非常重要的特性是，和函数返回一样，对于栈中的自动类对象，类的析构函数将被调用。



## 4. 其他特性

当抛出一个异常时，编译器会创建一个临时的异常对象。

这个临时对象是原始异常对象的副本，即使在 `catch` 块中使用引用来捕获异常。

```cpp
class Problem {
    // ...
};

void super() throw(Problem) {
    if (/* oh no */) {
        // 构造 Problem 对象
        Problem oops;
        // 抛出异常
        throw oops;
    }
}

int main() {
    try {
        super();
    } catch (Problem& p) {
        // 处理异常
        // ...
    }

    return 0;
}
```

`super` 函数抛出了一个 `Problem` 类型的异常。

这个异常被 `catch` 块捕获，`catch` 块中的 `p` 是 `oops` 的副本，而不是 `oops` 本身。

这是因为在 `super` 函数执行完毕后，`oops` 对象将被销毁，所以 `catch` 块中的 `p` 必须是 `oops` 的副本。



将引发异常和创建对象组合在一起将更简单：

```cpp
// 直接在 throw 语句中创建并抛出 Problem 对象
throw Problem();
```



基类引用可以执行派生类对象，异常规范中只需列出一个基类引用，它将与任何派生类对象匹配。

使用省略号来表示捕获所有异常。

需要注意它们的层次关系：

```cpp
class bad_1 { ... };
class bad_2 : public bad_1 { ... };
class bad_3 : public bad_2 { ... };

try{

}catch(bad_3 & be){

}catch(bad_2 & be){

}catch(bad_1 & be){

}catch(...){ // 捕获所有异常

}
```

如果将bad_1类放在最上面的catch，那么他会捕获bad_1、bad_2、bad_3 这三个类所有的异常。



## 5. 未捕获异常

当抛出一个异常，但没有任何catch能捕获它时，则称之为“未捕获异常”。

当出现"未捕获异常"时，程序会自动调用terminate函数，terminate会调用abort函数来终止程序。



throw 语句可以不带任何参数。这种情况下，它会抛出一个匿名的异常。 

匿名异常可以被 `catch(...)` 捕获，如果匿名异常没有被捕获，则变成一个“未捕获异常”。



可以通过set_terminate函数设置terminate调用指定的函数（而不是abort函数）。

set_terminate函数接受一个参数，参数为函数指针，指向没有参数类型，返回值为void的函数。

```cpp
#include <iostream>
#include <exception>
#include <cstdlib>

// 自定义的 terminate_handler
void myTerminate() {
    std::cerr << "未捕获的异常，程序终止。\n";
    std::abort();
}

int main() {
    // 设置自定义的 terminate_handler
    std::set_terminate(myTerminate);

    // 抛出一个未捕获的异常
    throw;

    return 0;
}

```





## 6. 意外异常

如果一个函数被声明为noexcept（不会抛出任何异常），但这个函数抛出了一个异常。

如果一个函数的异常规范中规定，只会抛出int和double类型的异常，但却抛出了一个char类型的异常。

这种情况会被称之为“意外异常”。



当发生“意外异常”时会调用unexpect函数，默认情况下，unexpect会调用terminate函数，然后terminate函数调用abort函数来结束程序。



set_unexpect函数可以设置unexpect函数调用用户自定义的函数。



在用户自定义的函数中可以进行两种操作：

1. 调用terminate（默认行为）、abort、exit函数来终止程序。
2. 再次抛出一个异常。



如果用户自定义的函数中再次抛出一个异常，则视抛出的异常来进行不同的操作：

1. 抛出新的异常，且（新的异常）与原异常规范匹配，则返回程序原地方，寻找匹配新异常的catch块。
2. 抛出新的异常，新的异常与原异常规范不匹配，且原异常规范不包含std::bad_exception类型，则调用terminate函数
3. 抛出新的异常，新的异常与原异常规范不匹配，且原异常规范包含std::bad_exception类型，则不匹配的异常将被std::bad_exception异常所取代。



## 7. 捕获自己的异常

这里有个问题。解退栈时，将删除栈中的变量 ar。但函数过早的终止意味着函数末尾的 delete[]语句被忽略。指针消失了，但它指向的内存块未被释放，并且不可访问。总之，这些内存被泄漏了。

```cpp
void test2(int n) {
    double *ar = new double[n];

    if (oh_no) {
        throw std::exception();	//抛出异常
    }

    // 如果没有异常发生，也需要释放内存
    delete[] ar;
}
```



为了避免这种情况，我们可以在抛出异常的函数中捕获异常，然后在 `catch` 块中执行清理工作，最后再重新抛出异常。

```cpp
void test2(int n) {
    double *ar = new double[n];

    try {
        // 可能会抛出异常的代码
        if (/* oh no */) {
            throw std::exception();
        }
    } catch (...) {
        // 在 catch 块中执行清理工作
        delete[] ar;

        // 重新抛出异常
        throw;
    }

    // 如果没有异常发生，也需要释放内存
    delete[] ar;
}
```

